[{"id":715605,"title":"MAAS register hardware fail","body":"<p>I can PXE boot my machines with MAAS but the registration always fails. None of them can be shown under the GUI 'Nodes' tab. Part of the error message I got on the screen is</p>\n\n<pre><code>url_helper.py[WARNING]: Calling http://169.254.169.254/2009-04-04/meta-data/instance-id failed [Errno 101] Network is unreachable)]\n</code></pre>\n\n<p>Any idea what might be the cause of this issue?</p>\n","related_questions":[{"id":555024,"title":"Is there a list of suggested hardware specs for trying Ubuntu Openstack?","body":"<p><a href=\"http://www.ubuntu.com/download/cloud/install-ubuntu-openstack\" rel=\"nofollow\">http://www.ubuntu.com/download/cloud/install-ubuntu-openstack</a> mentions needing 7 computers with two hard disks and at least two with dual nics.  However, it doesn't mention any CPU/storage requirements, nor does it say what these seven will do.</p>\n\n<p>Does anyone know what services each of the initial seven required computers runs?  I'm looking at building out a test environment, but want to make sure that I have the correct hardware the first time.</p>\n"},{"id":668575,"title":"openstack-install hangs registering against landscape","body":"<p>I'm behind a proxy, and ran <code>sudo openstack-install --http-proxy myproxy:port --https-proxy myproxy:port</code>, and then selected the landscape autopilot. The script made it through bootstrapping Juju, praparing Landscape and Deploying landscape, but now it's going on 4000 seconds registering against landscape, and still says it's downloading the latest landscape autopilot bundle. Is it normal for this script to take this long, or could there be more proxy configuration I need to do to download the latest landscape autopilot bundle? I'm trying to follow instructions from here <a href=\"http://www.ubuntu.com/download/cloud/install-ubuntu-openstack\" rel=\"nofollow\">http://www.ubuntu.com/download/cloud/install-ubuntu-openstack</a>. Thank you.</p>\n"},{"id":599209,"title":"cloud init fails on instance","body":"<p>I setup Ubuntu Openstack using Autopilot Installer / MAAS. When I try booting the VM the cloud-init fails to get metadata. Here's the Instance log (partial)</p>\n\n<pre>\ncloud-init-nonet[25.04]: static networking is now up\n * Starting configure network device[74G[ OK ]\nCloud-init v. 0.7.5 running 'init' at Fri, 20 Mar 2015 16:43:33 +0000. Up 25.26 seconds.\nci-info: ++++++++++++++++++++++++++Net device info+++++++++++++++++++++++++++\nci-info: +--------+------+--------------+---------------+-------------------+\nci-info: | Device |  Up  |   Address    |      Mask     |     Hw-Address    |\nci-info: +--------+------+--------------+---------------+-------------------+\nci-info: |   lo   | True |  127.0.0.1   |   255.0.0.0   |         .         |\nci-info: |  eth0  | True | 192.168.1.21 | 255.255.255.0 | fa:16:3e:ab:ac:16 |\nci-info: +--------+------+--------------+---------------+-------------------+\nci-info: +++++++++++++++++++++++++++++Route info++++++++++++++++++++++++++++++\nci-info: +-------+-------------+---------+---------------+-----------+-------+\nci-info: | Route | Destination | Gateway |    Genmask    | Interface | Flags |\nci-info: +-------+-------------+---------+---------------+-----------+-------+\nci-info: |   0   | 192.168.1.0 | 0.0.0.0 | 255.255.255.0 |    eth0   |   U   |\nci-info: +-------+-------------+---------+---------------+-----------+-------+\n2015-03-20 16:43:33,409 - url_helper.py[WARNING]: Calling 'http://169.254.169.254/2009-04-04/meta-data/instance-id' failed [0/120s]: request error [HTTPConnectionPool(host='169.254.169.254', port=80): Max retries exceeded with url: /2009-04-04/meta-data/instance-id (Caused by : [Errno 101] Network is unreachable)]\n2015-03-20 16:43:34,422 - url_helper.py[WARNING]: Calling 'http://169.254.169.254/2009-04-04/meta-data/instance-id' failed [1/120s]: request error [HTTPConnectionPool(host='169.254.169.254', port=80): Max retries exceeded with url: /2009-04-04/meta-data/instance-id (Caused by : [Errno 101] Network is unreachable)]\n2015-03-20 16:43:35,431 - url_helper.py[WARNING]: Calling 'http://169.254.169.254/2009-04-04/meta-data/instance-id' failed [2/120s]: request error [HTTPConnectionPool(host='169.254.169.254', port=80): Max retries exceeded with url: /2009-04-04/meta-data/instance-id (Caused by : [Errno 101] Network is unreachable)]\n2015-03-20 16:43:36,435 - url_helper.py[WARNING]: Calling 'http://169.254.169.254/2009-04-04/meta-data/instance-id' failed [3/120s]: request error [HTTPConnectionPool(host='169.254.169.254', port=80): Max retries exceeded with url: /2009-04-04/meta-data/instance-id (Caused by : [Errno 101] Network is unreachable)]\n2015-03-20 16:43:37,440 - url_helper.py[WARNING]: Calling 'http://169.254.169.254/2009-04-04/meta-data/instance-id' failed [4/120s]: request error [HTTPConnectionPool(host='169.254.169.254', port=80): Max retries exceeded with url: /2009-04-04/meta-data/instance-id (Caused by : [Errno 101] Network is unreachable)]\n2015-03-20 16:43:38,444 - url_helper.py[WARNING]: Calling 'http://169.254.169.254/2009-04-04/meta-data/instance-id' failed [5/120s]: request error [HTTPConnectionPool(host='169.254.169.254', port=80): Max retries exceeded with url: /2009-04-04/meta-data/instance-id (Caused by : [Errno 101] Network is unreachable)]\n2015-03-20 16:43:40,449 - url_helper.py[WARNING]: Calling 'http://169.254.169.254/2009-04-04/meta-data/instance-id' failed [7/120s]: request error [HTTPConnectionPool(host='169.254.169.254', port=80): Max retries exceeded with url: /2009-04-04/meta-data/instance-id (Caused by : [Errno 101] Network is unreachable)]\n2015-03-20 16:43:42,455 - url_helper.py[WARNING]: Calling 'http://169.254.169.254/2009-04-04/meta-data/instance-id' failed [9/120s]: request error [HTTPConnectionPool(host='169.254.169.254', port=80): Max retries exceeded with url: /2009-04-04/meta-data/instance-id (Caused by : [Errno 101] Network is unreachable)]\n2015-03-20 16:43:44,460 - url_helper.py[WARNING]: Calling 'http://169.254.169.254/2009-04-04/meta-data/instance-id' failed [11/120s]: request error [HTTPConnectionPool(host='169.254.169.254', port=80): Max retries exceeded with url: /2009-04-04/meta-data/instance-id (Caused by : [Errno 101] Network is unreachable)]\n2015-03-20 16:43:46,466 - url_helper.py[WARNING]: Calling 'http://169.254.169.254/2009-04-04/meta-data/instance-id' failed [13/120s]: request error [HTTPConnectionPool(host='169.254.169.254', port=80): Max retries exceeded with url: /2009-04-04/meta-data/instance-id (Caused by : [Errno 101] Network is unreachable)]\n2015-03-20 16:43:48,472 - url_helper.py[WARNING]: Calling 'http://169.254.169.254/2009-04-04/meta-data/instance-id' failed [15/120s]: request error [HTTPConnectionPool(host='169.254.169.254', port=80): Max retries exceeded with url: /2009-04-04/meta-data/instance-id (Caused by : [Errno 101] Network is unreachable)]\n2015-03-20 16:43:51,484 - url_helper.py[WARNING]: Calling 'http://169.254.169.254/2009-04-04/meta-data/instance-id' failed [18/120s]: request error [HTTPConnectionPool(host='169.254.169.254', port=80): Max retries exceeded with url: /2009-04-04/meta-data/instance-id (Caused by : [Errno 101] Network is unreachable)]\n2015-03-20 16:43:54,491 - url_helper.py[WARNING]: Calling 'http://169.254.169.254/2009-04-04/meta-data/instance-id' failed [21/120s]: request error [HTTPConnectionPool(host='169.254.169.254', port=80): Max retries exceeded with url: /2009-04-04/meta-data/instance-id (Caused by : [Errno 101] Network is unreachable)]\n2015-03-20 16:43:57,503 - url_helper.py[WARNING]: Calling 'http://169.254.169.254/2009-04-04/meta-data/instance-id' failed [24/120s]: request error [HTTPConnectionPool(host='169.254.169.254', port=80): Max retries exceeded with url: /2009-04-04/meta-data/instance-id (Caused by : [Errno 101] Network is unreachable)]\n2015-03-20 16:44:00,520 - url_helper.py[WARNING]: Calling 'http://169.254.169.254/2009-04-04/meta-data/instance-id' failed [27/120s]: request error [HTTPConnectionPool(host='169.254.169.254', port=80): Max retries exceeded with url: /2009-04-04/meta-data/instance-id (Caused by : [Errno 101] Network is unreachable)]\n2015-03-20 16:44:03,541 - url_helper.py[WARNING]: Calling 'http://169.254.169.254/2009-04-04/meta-data/instance-id' failed [30/120s]: request error [HTTPConnectionPool(host='169.254.169.254', port=80): Max retries exceeded with url: /2009-04-04/meta-data/instance-id (Caused by : [Errno 101] Network is unreachable)]\n2015-03-20 16:44:07,556 - url_helper.py[WARNING]: Calling 'http://169.254.169.254/2009-04-04/meta-data/instance-id' failed [34/120s]: request error [HTTPConnectionPool(host='169.254.169.254', port=80): Max retries exceeded with url: /2009-04-04/meta-data/instance-id (Caused by : [Errno 101] Network is unreachable)]\n2015-03-20 16:44:11,569 - url_helper.py[WARNING]: Calling 'http://169.254.169.254/2009-04-04/meta-data/instance-id' failed [38/120s]: request error [HTTPConnectionPool(host='169.254.169.254', port=80): Max retries exceeded with url: /2009-04-04/meta-data/instance-id (Caused by : [Errno 101] Network is unreachable)]\n2015-03-20 16:44:15,580 - url_helper.py[WARNING]: Calling 'http://169.254.169.254/2009-04-04/meta-data/instance-id' failed [42/120s]: request error [HTTPConnectionPool(host='169.254.169.254', port=80): Max retries exceeded with url: /2009-04-04/meta-data/instance-id (Caused by : [Errno 101] Network is unreachable)]\n2015-03-20 16:44:19,594 - url_helper.py[WARNING]: Calling 'http://169.254.169.254/2009-04-04/meta-data/instance-id' failed [46/120s]: request error [HTTPConnectionPool(host='169.254.169.254', port=80): Max retries exceeded with url: /2009-04-04/meta-data/instance-id (Caused by : [Errno 101] Network is unreachable)]\n2015-03-20 16:44:23,607 - url_helper.py[WARNING]: Calling 'http://169.254.169.254/2009-04-04/meta-data/instance-id' failed [50/120s]: request error [HTTPConnectionPool(host='169.254.169.254', port=80): Max retries exceeded with url: /2009-04-04/meta-data/instance-id (Caused by : [Errno 101] Network is unreachable)]\n2015-03-20 16:44:28,622 - url_helper.py[WARNING]: Calling 'http://169.254.169.254/2009-04-04/meta-data/instance-id' failed [55/120s]: request error [HTTPConnectionPool(host='169.254.169.254', port=80): Max retries exceeded with url: /2009-04-04/meta-data/instance-id (Caused by : [Errno 101] Network is unreachable)]\n2015-03-20 16:44:33,641 - url_helper.py[WARNING]: Calling 'http://169.254.169.254/2009-04-04/meta-data/instance-id' failed [60/120s]: request error [HTTPConnectionPool(host='169.254.169.254', port=80): Max retries exceeded with url: /2009-04-04/meta-data/instance-id (Caused by : [Errno 101] Network is unreachable)]\n2015-03-20 16:44:38,670 - url_helper.py[WARNING]: Calling 'http://169.254.169.254/2009-04-04/meta-data/instance-id' failed [65/120s]: request error [HTTPConnectionPool(host='169.254.169.254', port=80): Max retries exceeded with url: /2009-04-04/meta-data/instance-id (Caused by : [Errno 101] Network is unreachable)]\n2015-03-20 16:44:43,690 - url_helper.py[WARNING]: Calling 'http://169.254.169.254/2009-04-04/meta-data/instance-id' failed [70/120s]: request error [HTTPConnectionPool(host='169.254.169.254', port=80): Max retries exceeded with url: /2009-04-04/meta-data/instance-id (Caused by : [Errno 101] Network is unreachable)]\n2015-03-20 16:44:48,710 - url_helper.py[WARNING]: Calling 'http://169.254.169.254/2009-04-04/meta-data/instance-id' failed [75/120s]: request error [HTTPConnectionPool(host='169.254.169.254', port=80): Max retries exceeded with url: /2009-04-04/meta-data/instance-id (Caused by : [Errno 101] Network is unreachable)]\n2015-03-20 16:44:54,726 - url_helper.py[WARNING]: Calling 'http://169.254.169.254/2009-04-04/meta-data/instance-id' failed [81/120s]: request error [HTTPConnectionPool(host='169.254.169.254', port=80): Max retries exceeded with url: /2009-04-04/meta-data/instance-id (Caused by : [Errno 101] Network is unreachable)]\n2015-03-20 16:45:00,741 - url_helper.py[WARNING]: Calling 'http://169.254.169.254/2009-04-04/meta-data/instance-id' failed [87/120s]: request error [HTTPConnectionPool(host='169.254.169.254', port=80): Max retries exceeded with url: /2009-04-04/meta-data/instance-id (Caused by : [Errno 101] Network is unreachable)]\n2015-03-20 16:45:06,757 - url_helper.py[WARNING]: Calling 'http://169.254.169.254/2009-04-04/meta-data/instance-id' failed [93/120s]: request error [HTTPConnectionPool(host='169.254.169.254', port=80): Max retries exceeded with url: /2009-04-04/meta-data/instance-id (Caused by : [Errno 101] Network is unreachable)]\n2015-03-20 16:45:12,770 - url_helper.py[WARNING]: Calling 'http://169.254.169.254/2009-04-04/meta-data/instance-id' failed [99/120s]: request error [HTTPConnectionPool(host='169.254.169.254', port=80): Max retries exceeded with url: /2009-04-04/meta-data/instance-id (Caused by : [Errno 101] Network is unreachable)]\n2015-03-20 16:45:18,790 - url_helper.py[WARNING]: Calling 'http://169.254.169.254/2009-04-04/meta-data/instance-id' failed [105/120s]: request error [HTTPConnectionPool(host='169.254.169.254', port=80): Max retries exceeded with url: /2009-04-04/meta-data/instance-id (Caused by : [Errno 101] Network is unreachable)]\n2015-03-20 16:45:25,805 - url_helper.py[WARNING]: Calling 'http://169.254.169.254/2009-04-04/meta-data/instance-id' failed [112/120s]: request error [HTTPConnectionPool(host='169.254.169.254', port=80): Max retries exceeded with url: /2009-04-04/meta-data/instance-id (Caused by : [Errno 101] Network is unreachable)]\n2015-03-20 16:45:32,830 - url_helper.py[WARNING]: Calling 'http://169.254.169.254/2009-04-04/meta-data/instance-id' failed [119/120s]: request error [HTTPConnectionPool(host='169.254.169.254', port=80): Max retries exceeded with url: /2009-04-04/meta-data/instance-id (Caused by : [Errno 101] Network is unreachable)]\n2015-03-20 16:45:39,843 - DataSourceEc2.py[CRITICAL]: Giving up on md from ['http://169.254.169.254/2009-04-04/meta-data/instance-id'] after 126 seconds\n2015-03-20 16:45:39,855 - url_helper.py[WARNING]: Calling 'http://192.168.1.20//latest/meta-data/instance-id' failed [0/120s]: request error [HTTPConnectionPool(host='192.168.1.20', port=80): Max retries exceeded with url: //latest/meta-data/instance-id (Caused by : [Errno 111] Connection refused)]\n2015-03-20 16:45:40,865 - url_helper.py[WARNING]: Calling 'http://192.168.1.20//latest/meta-data/instance-id' failed [1/120s]: request error [HTTPConnectionPool(host='192.168.1.20', port=80): Max retries exceeded with url: //latest/meta-data/instance-id (Caused by : [Errno 111] Connection refused)]\n2015-03-20 16:45:41,879 - url_helper.py[WARNING]: Calling 'http://192.168.1.20//latest/meta-data/instance-id' failed [2/120s]: request error [HTTPConnectionPool(host='192.168.1.20', port=80): Max retries exceeded with url: //latest/meta-data/instance-id (Caused by : [Errno 111] Connection refused)]\n2015-03-20 16:45:42,884 - url_helper.py[WARNING]: Calling 'http://192.168.1.20//latest/meta-data/instance-id' failed [3/120s]: request error [HTTPConnectionPool(host='192.168.1.20', port=80): Max retries exceeded with url: //latest/meta-data/instance-id (Caused by : [Errno 111] Connection refused)]\n2015-03-20 16:45:43,889 - url_helper.py[WARNING]: Calling 'http://192.168.1.20//latest/meta-data/instance-id' failed [4/120s]: request error [HTTPConnectionPool(host='192.168.1.20', port=80): Max retries exceeded with url: //latest/meta-data/instance-id (Caused by : [Errno 111] Connection refused)]\n2015-03-20 16:45:44,894 - url_helper.py[WARNING]: Calling 'http://192.168.1.20//latest/meta-data/instance-id' failed [5/120s]: request error [HTTPConnectionPool(host='192.168.1.20', port=80): Max retries exceeded with url: //latest/meta-data/instance-id (Caused by : [Errno 111] Connection refused)]\n2015-03-20 16:45:46,900 - url_helper.py[WARNING]: Calling 'http://192.168.1.20//latest/meta-data/instance-id' failed [7/120s]: request error [HTTPConnectionPool(host='192.168.1.20', port=80): Max retries exceeded with url: //latest/meta-data/instance-id (Caused by : [Errno 111] Connection refused)]\n2015-03-20 16:45:48,912 - url_helper.py[WARNING]: Calling 'http://192.168.1.20//latest/meta-data/instance-id' failed [9/120s]: request error [HTTPConnectionPool(host='192.168.1.20', port=80): Max retries exceeded with url: //latest/meta-data/instance-id (Caused by : [Errno 111] Connection refused)]\n2015-03-20 16:45:50,918 - url_helper.py[WARNING]: Calling 'http://192.168.1.20//latest/meta-data/instance-id' failed [11/120s]: request error [HTTPConnectionPool(host='192.168.1.20', port=80): Max retries exceeded with url: //latest/meta-data/instance-id (Caused by : [Errno 111] Connection refused)]\n2015-03-20 16:45:52,924 - url_helper.py[WARNING]: Calling 'http://192.168.1.20//latest/meta-data/instance-id' failed [13/120s]: request error [HTTPConnectionPool(host='192.168.1.20', port=80): Max retries exceeded with url: //latest/meta-data/instance-id (Caused by : [Errno 111] Connection refused)]\n2015-03-20 16:45:54,930 - url_helper.py[WARNING]: Calling 'http://192.168.1.20//latest/meta-data/instance-id' failed [15/120s]: request error [HTTPConnectionPool(host='192.168.1.20', port=80): Max retries exceeded with url: //latest/meta-data/instance-id (Caused by : [Errno 111] Connection refused)]\n2015-03-20 16:45:57,943 - url_helper.py[WARNING]: Calling 'http://192.168.1.20//latest/meta-data/instance-id' failed [18/120s]: request error [HTTPConnectionPool(host='192.168.1.20', port=80): Max retries exceeded with url: //latest/meta-data/instance-id (Caused by : [Errno 111] Connection refused)]\n2015-03-20 16:46:00,956 - url_helper.py[WARNING]: Calling 'http://192.168.1.20//latest/meta-data/instance-id' failed [21/120s]: request error [HTTPConnectionPool(host='192.168.1.20', port=80): Max retries exceeded with url: //latest/meta-data/instance-id (Caused by : [Errno 111] Connection refused)]\n2015-03-20 16:46:03,970 - url_helper.py[WARNING]: Calling 'http://192.168.1.20//latest/meta-data/instance-id' failed [24/120s]: request error [HTTPConnectionPool(host='192.168.1.20', port=80): Max retries exceeded with url: //latest/meta-data/instance-id (Caused by : [Errno 111] Connection refused)]\n</pre>\n\n<p>its also interesting to note that the IP went from 169.254.169.254 to 192.168.1.20 (192.x is the DHCP agent IP). </p>\n\n<p>Any ideas where I can start?</p>\n"},{"id":599162,"title":"Error to deploy openstack-autopilot: &quot;failed status&quot; on a virtual environment KVM","body":"<p>after to run the install of openstack-autopilot, \nsome vnode went in \"failed\" status some others are in deployed and on Landscape I saw the progress of the deploy for the rest</p>\n\n<p>one question is: \"it's normal that?\"\nsecond question: \"is there a way to re-deploy the vnodes in \"failed\" status?\"</p>\n\n<p><img src=\"http://i.stack.imgur.com/SSHqk.png\" alt=\"enter image description here\"></p>\n\n<p>at the end after some minutes I've received that</p>\n\n<p><img src=\"http://i.stack.imgur.com/xuIfD.png\" alt=\"enter image description here\"></p>\n"},{"id":584434,"title":"Landscape fails when using openstack-installer (even /experimental fails)","body":"<p>Here's the pastebin log</p>\n\n<p><a href=\"http://pastebin.com/cXjC8rzP\" rel=\"nofollow\">http://pastebin.com/cXjC8rzP</a></p>\n\n<p>We are doing an Ubuntu cloud PoC, and are in the process of going with a 100 node license.</p>\n"},{"id":593754,"title":"What are the requirements for MAAS and OpenStack?","body":"<p>What is the minimum number of computers needed to install MAAS and OpenStack? Also, what are the hardware requirements for all nodes with OpenStack?</p>\n"},{"id":585380,"title":"Login credentials for nodes in MaaS node list after obtaining deployed state","body":"<p>I have a total of three machines. I have installed MaaS in one of my machines and the other two machines were added to the MaaS nodes list and kept in ready state.</p>\n\n<p>When I run the fourth step given in the <a href=\"http://www.ubuntu.com/download/cloud/install-ubuntu-openstack\" rel=\"nofollow\">Installing The Canonical Distribution of Ubuntu OpenStack</a> Ubuntu documentation, both the machines went to the deployed state.</p>\n\n<p>Both the nodes in the deployed state are asking for login and password, and the Ubuntu OpenStack installer screen is running for too long a time. I don't know to how to proceed. Please help me. I am looking for this to do simple job scheduling in a cloud environment using OpenStack. </p>\n"},{"id":584145,"title":"How to get Landscape running on MAAS on Ubuntu OrangeBox?","body":"<p>We have purchased several Ubuntu OrangeBoxes, and are trying to get a prototype environment running, but it's proving to be difficult as there is very little documentation or contact points available for the Orange Box.</p>\n\n<p>After struggling for a long time with several functions in the tech stack not working properly behind a proxy (boot image sync, juju ++), we're now stuck at Landscape deployment on MAAS.</p>\n\n<p>Initial connection to MAAS in Landscape fails on install prerequisites check, as Landscape requires a minimum of 5 nodes with 2 HDDs available in MAAS to continue. The NUCs in the OrangeBox only have one HDD each, so the install will not run.</p>\n\n<p>Please advise.</p>\n"},{"id":577336,"title":"Installing Ubuntu Openstack unable to add hardware","body":"<p>I'm following the \"Installing Ubuntu Openstack\" insructions and stuck at step #9. I have 8 servers commissioned and in the \"Ready\" state. The checklist is all green in Landscape, but there is nothing in the \"Add Hardware\" section.</p>\n\n<p>No errors or hints as to where to look next. Even if you don't know the answer, if you could suggest log files to review I'd appreciate it. </p>\n"},{"id":563063,"title":"Final Hardware Selection Step in Landscape Openstack Install","body":"<p>I'm on the last step before my Landscape Openstack install should begin. Configuration is chosen and 5 machines (KVM virtual machines managed by MAAS) are selected. (green checkmark)</p>\n\n<p>But, the last step - Add at least one machine on the public network remains grayed-out and I don't see any way to select the last system.  I'm assuming the last system is the MAAS KVM machine with the two ethernet NICs.</p>\n\n<p>If I add the 6th system along with the required 5, that does not help.</p>\n\n<p>How can I get through this last step?</p>\n\n<p>Have I incorrectly set something on Open vSwitch where a public network is set up? </p>\n\n<p>How does this process work?</p>\n"}]}]